Workbook
Name Slicer_Month: #N/A
Name Slicer_Year: #N/A

Sheet DASHBOARD

Sheet DASHBOARD Light

Sheet Processing
A1: Employee Categories | B1: Management | C1: Administrative staff | D1: Sales department | E1: Production department | F1: Logistics department | I1: Total Payroll | J1: Payroll Work Hour Representation | N1: Performance
A2: Value | B2: =GETPIVOTDATA(""&B1,Control!$A$3) -> 60760 | C2: =GETPIVOTDATA(""&C1,Control!$A$3) -> 50950 | D2: =GETPIVOTDATA(""&D1,Control!$A$3) -> 53140 | E2: =GETPIVOTDATA(""&E1,Control!$A$3) -> 38170 | F2: =GETPIVOTDATA(""&F1,Control!$A$3) -> 34660 | I2: =GETPIVOTDATA("Sum of Payroll",Control!$A$3) -> 118840 | J2: =GETPIVOTDATA("Average of Standard Hours",Control!$A$3) -> 0.72 | K2: =100%-J2 -> 0.28 | N2: KPI | O2: MoM | R2: 10 | S2: 10 | T2: 10 | U2: 10 | V2: 10
A3: % | B3: =B2/MAX($B$2:$F$2) -> 1 | C3: =C2/MAX($B$2:$F$2) -> 0.8385451 | D3: =D2/MAX($B$2:$F$2) -> 0.87458855 | E3: =E2/MAX($B$2:$F$2) -> 0.62820935 | F3: =F2/MAX($B$2:$F$2) -> 0.57044108 | M3: A | N3: =GETPIVOTDATA(""&M3,Control!$A$3) -> 0.62 | O3: =GETPIVOTDATA(M3&2,Control!$A$3) -> 0.35 | P3: Management | R3: 10 | S3: 10 | T3: 10 | U3: 10 | V3: 10
A4: Total | B4: =SUM(B2:F2) -> 237680 | C4: =B4 -> 237680 | M4: B | N4: =GETPIVOTDATA(""&M4,Control!$A$3) -> 0.87 | O4: =GETPIVOTDATA(M4&2,Control!$A$3) -> 0.45 | P4: Administrative Staff | R4: 10 | S4: 10 | T4: 10 | U4: 10 | V4: 10
M5: C | N5: =GETPIVOTDATA(""&M5,Control!$A$3) -> 1.18 | O5: =GETPIVOTDATA(M5&2,Control!$A$3) -> 0.63 | P5: Sales Department | R5: 10 | S5: 10 | T5: 10 | U5: 10 | V5: 10
B6: Asset 1 | D6: Asset 2 | F6: Asset 3 | H6: Asset 4 | J6: Asset 5 | K6: Sectors | M6: D | N6: =GETPIVOTDATA(""&M6,Control!$A$3) -> 0.38 | O6: =GETPIVOTDATA(M6&2,Control!$A$3) -> 0.61 | P6: Production Department
A7: Done | B7: {=(100%-B9)*INDEX($B$3:$F$3,1,B10)} -> 0.75 | C7: {=(100%-C9)*INDEX($B$3:$F$3,1,C10)} -> 0.75 | D7: {=(100%-D9)*INDEX($B$3:$F$3,1,D10)} -> 0.62890882 | E7: {=(100%-E9)*INDEX($B$3:$F$3,1,E10)} -> 0.62890882 | F7: {=(100%-F9)*INDEX($B$3:$F$3,1,F10)} -> 0.65594141 | G7: {=(100%-G9)*INDEX($B$3:$F$3,1,G10)} -> 0.65594141 | H7: {=(100%-H9)*INDEX($B$3:$F$3,1,H10)} -> 0.47115701 | I7: {=(100%-I9)*INDEX($B$3:$F$3,1,I10)} -> 0.47115701 | J7: {=(100%-J9)*INDEX($B$3:$F$3,1,J10)} -> 0.42783081 | K7: 0.75 | M7: E | N7: =GETPIVOTDATA(""&M7,Control!$A$3) -> 0.36 | O7: =GETPIVOTDATA(M7&2,Control!$A$3) -> 0.53 | P7: Logistics Department
A8: Running | B8: =100%-B9-B7 -> 0 | C8: =100%-C9-C7 -> 0 | D8: =100%-D9-D7 -> 0.12109118 | E8: =100%-E9-E7 -> 0.12109118 | F8: =100%-F9-F7 -> 0.094058591 | G8: =100%-G9-G7 -> 0.094058591 | H8: =100%-H9-H7 -> 0.27884299 | I8: =100%-I9-I7 -> 0.27884299 | J8: =100%-J9-J7 -> 0.32216919 | K8: 0 | M8: Total | N8: =AVERAGE(N3:N7) -> 0.682 | O8: =AVERAGE(O3:O7) -> 0.514
A9: Average | B9: =$K$9 -> 0.25 | C9: =$K$9 -> 0.25 | D9: =$K$9 -> 0.25 | E9: =$K$9 -> 0.25 | F9: =$K$9 -> 0.25 | G9: =$K$9 -> 0.25 | H9: =$K$9 -> 0.25 | I9: =$K$9 -> 0.25 | J9: =$K$9 -> 0.25 | K9: =100%-K7 -> 0.25
A10: =AVERAGE(J7,H7,F7,D7,B7) -> 0.58676761 | B10: 1 | C10: 1 | D10: 2 | E10: 2 | F10: 3 | G10: 3 | H10: 4 | I10: 4 | J10: 5 | M10: Location | N10: Payroll Distribution by Location
M11: Head Office | N11: =GETPIVOTDATA(""&M11,Control!$A$3) -> 0.28 | O11: =$N11 -> 0.28 | P11: =$N11 -> 0.28
A12: Payroll Forecast | B12: Forecast | C12: Actual | D12: Cursor | E12: Label | F12: Payroll Fundation | G12: Payroll | H12: Annual Payroll Plan | I12: Cursor | M12: Regional Offices | N12: =GETPIVOTDATA(""&M12,Control!$A$3) -> 0.21 | O12: =$N12 -> 0.21 | P12: =$N12 -> 0.21
A13: JAN | B13: =GETPIVOTDATA(""&B$12,Control!$A$20,"Month",""&$A13) -> 50000 | C13: =GETPIVOTDATA(""&C$12,Control!$A$20,"Month",""&$A13) -> 40000 | D13: =IFERROR(GETPIVOTDATA(""&C$12,Control!$A$3,"Month",""&$A13),NA()) -> #N/A | E13: =IF(ISNA(D13),"",ROUND(D13/1000,0)&"k") | H13: =H14 -> 60000 | M13: Regional Branches | N13: =GETPIVOTDATA(""&M13,Control!$A$3) -> 0.13 | O13: =$N13 -> 0.13 | P13: =$N13 -> 0.13
A14: FEB | B14: =GETPIVOTDATA(""&B$12,Control!$A$20,"Month",""&$A14) -> 40000 | C14: =GETPIVOTDATA(""&C$12,Control!$A$20,"Month",""&$A14) -> 50000 | D14: =IFERROR(GETPIVOTDATA(""&C$12,Control!$A$3,"Month",""&$A14),NA()) -> #N/A | E14: =IF(ISNA(D14),"",ROUND(D14/1000,0)&"k") | F14: JAN | G14: =GETPIVOTDATA(""&G$12,Control!$A$20,"Month",""&$F14) -> 53818 | H14: =GETPIVOTDATA(""&H$12,Control!$A$20,"Month",""&$F14) -> 60000 | I14: =IFERROR(GETPIVOTDATA("Sum of Payroll",Control!$A$3,"Month",""&F14),NA()) -> #N/A | M14: Remote Employees | N14: =GETPIVOTDATA(""&M14,Control!$A$3) -> 0.05 | O14: =$N14 -> 0.05 | P14: =$N14 -> 0.05
A15: MAR | B15: =GETPIVOTDATA(""&B$12,Control!$A$20,"Month",""&$A15) -> 50000 | C15: =GETPIVOTDATA(""&C$12,Control!$A$20,"Month",""&$A15) -> 35000 | D15: =IFERROR(GETPIVOTDATA(""&C$12,Control!$A$3,"Month",""&$A15),NA()) -> #N/A | E15: =IF(ISNA(D15),"",ROUND(D15/1000,0)&"k") | F15: FEB | G15: =GETPIVOTDATA(""&G$12,Control!$A$20,"Month",""&$F15) -> 76798 | H15: =GETPIVOTDATA(""&H$12,Control!$A$20,"Month",""&$F15) -> 60000 | I15: =IFERROR(GETPIVOTDATA("Sum of Payroll",Control!$A$3,"Month",""&F15),NA()) -> #N/A | M15: Outsourcing | N15: =GETPIVOTDATA(""&M15,Control!$A$3) -> 0.33 | O15: =$N15 -> 0.33 | P15: =$N15 -> 0.33
A16: APR | B16: =GETPIVOTDATA(""&B$12,Control!$A$20,"Month",""&$A16) -> 45000 | C16: =GETPIVOTDATA(""&C$12,Control!$A$20,"Month",""&$A16) -> 55000 | D16: =IFERROR(GETPIVOTDATA(""&C$12,Control!$A$3,"Month",""&$A16),NA()) -> #N/A | E16: =IF(ISNA(D16),"",ROUND(D16/1000,0)&"k") | F16: MAR | G16: =GETPIVOTDATA(""&G$12,Control!$A$20,"Month",""&$F16) -> 78380 | H16: =GETPIVOTDATA(""&H$12,Control!$A$20,"Month",""&$F16) -> 60000 | I16: =IFERROR(GETPIVOTDATA("Sum of Payroll",Control!$A$3,"Month",""&F16),NA()) -> #N/A
A17: MAY | B17: =GETPIVOTDATA(""&B$12,Control!$A$20,"Month",""&$A17) -> 70000 | C17: =GETPIVOTDATA(""&C$12,Control!$A$20,"Month",""&$A17) -> 60000 | D17: =IFERROR(GETPIVOTDATA(""&C$12,Control!$A$3,"Month",""&$A17),NA()) -> #N/A | E17: =IF(ISNA(D17),"",ROUND(D17/1000,0)&"k") | F17: APR | G17: =GETPIVOTDATA(""&G$12,Control!$A$20,"Month",""&$F17) -> 80403 | H17: =GETPIVOTDATA(""&H$12,Control!$A$20,"Month",""&$F17) -> 60000 | I17: =IFERROR(GETPIVOTDATA("Sum of Payroll",Control!$A$3,"Month",""&F17),NA()) -> #N/A | M17: =CHOOSE($O$24,"",M18) | N17: =CHOOSE($O$24,N18,"") -> Bonus | O17: =O24+2 -> 3
A18: JUN | B18: =GETPIVOTDATA(""&B$12,Control!$A$20,"Month",""&$A18) -> 60000 | C18: =GETPIVOTDATA(""&C$12,Control!$A$20,"Month",""&$A18) -> 80000 | D18: =IFERROR(GETPIVOTDATA(""&C$12,Control!$A$3,"Month",""&$A18),NA()) -> #N/A | E18: =IF(ISNA(D18),"",ROUND(D18/1000,0)&"k") | F18: MAY | G18: =GETPIVOTDATA(""&G$12,Control!$A$20,"Month",""&$F18) -> 110090 | H18: =GETPIVOTDATA(""&H$12,Control!$A$20,"Month",""&$F18) -> 60000 | I18: =IFERROR(GETPIVOTDATA("Sum of Payroll",Control!$A$3,"Month",""&F18),NA()) -> #N/A | K18: Top 5 Employees | L18: 1 | M18: Salary | N18: Bonus | O18: sort by | P18: Total | Q18: Bonus | R18: Base Salary | S18: Empls | T18: Total | U18: Bonus | V18: Base Salary
A19: JUL | B19: =GETPIVOTDATA(""&B$12,Control!$A$20,"Month",""&$A19) -> 80000 | C19: =GETPIVOTDATA(""&C$12,Control!$A$20,"Month",""&$A19) -> 95000 | D19: =IFERROR(GETPIVOTDATA(""&C$12,Control!$A$3,"Month",""&$A19),NA()) -> #N/A | E19: =IF(ISNA(D19),"",ROUND(D19/1000,0)&"k") | F19: JUN | G19: =GETPIVOTDATA(""&G$12,Control!$A$20,"Month",""&$F19) -> 127270 | H19: =GETPIVOTDATA(""&H$12,Control!$A$20,"Month",""&$F19) -> 60000 | I19: =IFERROR(GETPIVOTDATA("Sum of Payroll",Control!$A$3,"Month",""&F19),NA()) -> #N/A | K19: =O19 -> Employee1 | L19: =$L$18 -> 1 | M19: =R19/MAX($P$19:$P$23)+$K$24 -> 0.77272727 | N19: =Q19/MAX($P$19:$P$23) -> 0.73484848 | O19: {=_xlfn._xlws.SORT(S19:V23,$O$17,-1)} -> Employee1 | P19: 13200 | Q19: 9700 | R19: 3500 | S19: Employee1 | T19: =SUM(U19:V19) -> 13200 | U19: =GETPIVOTDATA(""&S19,Control!$A$3) -> 9700 | V19: =GETPIVOTDATA(S19&"BS",Control!$A$3) -> 3500
A20: AUG | B20: =GETPIVOTDATA(""&B$12,Control!$A$20,"Month",""&$A20) -> 70000 | C20: =GETPIVOTDATA(""&C$12,Control!$A$20,"Month",""&$A20) -> 90000 | D20: =IFERROR(GETPIVOTDATA(""&C$12,Control!$A$3,"Month",""&$A20),NA()) -> #N/A | E20: =IF(ISNA(D20),"",ROUND(D20/1000,0)&"k") | F20: JUL | G20: =GETPIVOTDATA(""&G$12,Control!$A$20,"Month",""&$F20) -> 127090 | H20: =GETPIVOTDATA(""&H$12,Control!$A$20,"Month",""&$F20) -> 60000 | I20: =IFERROR(GETPIVOTDATA("Sum of Payroll",Control!$A$3,"Month",""&F20),NA()) -> #N/A | K20: =O20 -> Employee5 | L20: =$L$18 -> 1 | M20: =R20/MAX($P$19:$P$23)+$K$24 -> 0.73484848 | N20: =Q20/MAX($P$19:$P$23) -> 0.45454545 | O20: Employee5 | P20: 9000 | Q20: 6000 | R20: 3000 | S20: Employee2 | T20: =SUM(U20:V20) -> 9400 | U20: =GETPIVOTDATA(""&S20,Control!$A$3) -> 2900 | V20: =GETPIVOTDATA(S20&"BS",Control!$A$3) -> 6500
A21: SEP | B21: =GETPIVOTDATA(""&B$12,Control!$A$20,"Month",""&$A21) -> 80000 | C21: =GETPIVOTDATA(""&C$12,Control!$A$20,"Month",""&$A21) -> 70000 | D21: =IFERROR(GETPIVOTDATA(""&C$12,Control!$A$3,"Month",""&$A21),NA()) -> #N/A | E21: =IF(ISNA(D21),"",ROUND(D21/1000,0)&"k") | F21: AUG | G21: =GETPIVOTDATA(""&G$12,Control!$A$20,"Month",""&$F21) -> 126645 | H21: =GETPIVOTDATA(""&H$12,Control!$A$20,"Month",""&$F21) -> 60000 | I21: =IFERROR(GETPIVOTDATA("Sum of Payroll",Control!$A$3,"Month",""&F21),NA()) -> #N/A | K21: =O21 -> Employee4 | L21: =$L$18 -> 1 | M21: =R21/MAX($P$19:$P$23)+$K$24 -> 0.95454545 | N21: =Q21/MAX($P$19:$P$23) -> 0.40151515 | O21: Employee4 | P21: 11200 | Q21: 5300 | R21: 5900 | S21: Employee3 | T21: =SUM(U21:V21) -> 7000 | U21: =GETPIVOTDATA(""&S21,Control!$A$3) -> 4600 | V21: =GETPIVOTDATA(S21&"BS",Control!$A$3) -> 2400
A22: OCT | B22: =GETPIVOTDATA(""&B$12,Control!$A$20,"Month",""&$A22) -> 100000 | C22: =GETPIVOTDATA(""&C$12,Control!$A$20,"Month",""&$A22) -> 80000 | D22: =IFERROR(GETPIVOTDATA(""&C$12,Control!$A$3,"Month",""&$A22),NA()) -> 80000 | E22: =IF(ISNA(D22),"",ROUND(D22/1000,0)&"k") -> 80k | F22: SEP | G22: =GETPIVOTDATA(""&G$12,Control!$A$20,"Month",""&$F22) -> 121425 | H22: =GETPIVOTDATA(""&H$12,Control!$A$20,"Month",""&$F22) -> 60000 | I22: =IFERROR(GETPIVOTDATA("Sum of Payroll",Control!$A$3,"Month",""&F22),NA()) -> #N/A | K22: =O22 -> Employee3 | L22: =$L$18 -> 1 | M22: =R22/MAX($P$19:$P$23)+$K$24 -> 0.68939394 | N22: =Q22/MAX($P$19:$P$23) -> 0.34848485 | O22: Employee3 | P22: 7000 | Q22: 4600 | R22: 2400 | S22: Employee4 | T22: =SUM(U22:V22) -> 11200 | U22: =GETPIVOTDATA(""&S22,Control!$A$3) -> 5300 | V22: =GETPIVOTDATA(S22&"BS",Control!$A$3) -> 5900
A23: NOV | B23: =GETPIVOTDATA(""&B$12,Control!$A$20,"Month",""&$A23) -> 95000 | C23: =GETPIVOTDATA(""&C$12,Control!$A$20,"Month",""&$A23) -> 60000 | D23: =IFERROR(GETPIVOTDATA(""&C$12,Control!$A$3,"Month",""&$A23),NA()) -> #N/A | E23: =IF(ISNA(D23),"",ROUND(D23/1000,0)&"k") | F23: OCT | G23: =GETPIVOTDATA(""&G$12,Control!$A$20,"Month",""&$F23) -> 118840 | H23: =GETPIVOTDATA(""&H$12,Control!$A$20,"Month",""&$F23) -> 60000 | I23: =IFERROR(GETPIVOTDATA("Sum of Payroll",Control!$A$3,"Month",""&F23),NA()) -> 118840 | K23: =O23 -> Employee2 | L23: =$L$18 -> 1 | M23: =R23/MAX($P$19:$P$23)+$K$24 -> 1 | N23: =Q23/MAX($P$19:$P$23) -> 0.21969697 | O23: Employee2 | P23: 9400 | Q23: 2900 | R23: 6500 | S23: Employee5 | T23: =SUM(U23:V23) -> 9000 | U23: =GETPIVOTDATA(""&S23,Control!$A$3) -> 6000 | V23: =GETPIVOTDATA(S23&"BS",Control!$A$3) -> 3000
A24: DEC | B24: =GETPIVOTDATA(""&B$12,Control!$A$20,"Month",""&$A24) -> 80000 | C24: =GETPIVOTDATA(""&C$12,Control!$A$20,"Month",""&$A24) -> 50000 | D24: =IFERROR(GETPIVOTDATA(""&C$12,Control!$A$3,"Month",""&$A24),NA()) -> #N/A | E24: =IF(ISNA(D24),"",ROUND(D24/1000,0)&"k") | F24: NOV | G24: =GETPIVOTDATA(""&G$12,Control!$A$20,"Month",""&$F24) -> 98685 | H24: =GETPIVOTDATA(""&H$12,Control!$A$20,"Month",""&$F24) -> 60000 | I24: =IFERROR(GETPIVOTDATA("Sum of Payroll",Control!$A$3,"Month",""&F24),NA()) -> #N/A | K24: =L18-L24 -> 0.50757576 | L24: =MAX(R19:R23)/MAX($P$19:$P$23) -> 0.49242424 | O24: 1
A25: Total | B25: 495000 | C25: 290000 | F25: DEC | G25: =GETPIVOTDATA(""&G$12,Control!$A$20,"Month",""&$F25) -> 98395 | H25: =GETPIVOTDATA(""&H$12,Control!$A$20,"Month",""&$F25) -> 60000 | I25: =IFERROR(GETPIVOTDATA("Sum of Payroll",Control!$A$3,"Month",""&F25),NA()) -> #N/A
H26: =H25 -> 60000 | N26: CHOOSE
A27: Year | B27: Month | I27: =GETPIVOTDATA("Sum of Payroll",Control!$A$3) -> 118840
A28: =MAX(Control!A37:A40) -> 2025 | B28: {=INDEX(Control!A4:A15,COUNTA(Control!A4:A16)-1)} -> OCT
A29: Day | B29: Shift 1 | C29: Shift 2 | D29: Shift 3 | E29: Shift 4 | G29: Working Time Heat Map | H29: Day | I29: Shift 1 | J29: Shift 2 | K29: Shift 3 | L29: Shift 4
A30: 1 | B30: {=INDEX('HOTMAP-DATA'!$D$2:$G$1345,MATCH($A$28&$B$28&$A30,'HOTMAP-DATA'!$A$2:$A$1345&'HOTMAP-DATA'!$B$2:$B$1345&'HOTMAP-DATA'!$C$2:$C$1345,0),COLUMN(A$1))} -> 3 | C30: {=INDEX('HOTMAP-DATA'!$D$2:$G$1345,MATCH($A$28&$B$28&$A30,'HOTMAP-DATA'!$A$2:$A$1345&'HOTMAP-DATA'!$B$2:$B$1345&'HOTMAP-DATA'!$C$2:$C$1345,0),COLUMN(B$1))} -> 2 | D30: {=INDEX('HOTMAP-DATA'!$D$2:$G$1345,MATCH($A$28&$B$28&$A30,'HOTMAP-DATA'!$A$2:$A$1345&'HOTMAP-DATA'!$B$2:$B$1345&'HOTMAP-DATA'!$C$2:$C$1345,0),COLUMN(C$1))} -> 2 | E30: {=INDEX('HOTMAP-DATA'!$D$2:$G$1345,MATCH($A$28&$B$28&$A30,'HOTMAP-DATA'!$A$2:$A$1345&'HOTMAP-DATA'!$B$2:$B$1345&'HOTMAP-DATA'!$C$2:$C$1345,0),COLUMN(D$1))} -> 2 | F30: Underwork | G30: 1 | H30: =INT((ROW(A1)-1)/4)+1 -> 1 | I30: {=INDEX(B$30:B$57,$H30)=$G30} -> FALSE | J30: {=INDEX(C$30:C$57,$H30)=$G30} -> FALSE | K30: {=INDEX(D$30:D$57,$H30)=$G30} -> FALSE | L30: {=INDEX(E$30:E$57,$H30)=$G30} -> FALSE | M30: TRUE | N30: TRUE | O30: TRUE | P30: TRUE
A31: 2 | B31: {=INDEX('HOTMAP-DATA'!$D$2:$G$1345,MATCH($A$28&$B$28&$A31,'HOTMAP-DATA'!$A$2:$A$1345&'HOTMAP-DATA'!$B$2:$B$1345&'HOTMAP-DATA'!$C$2:$C$1345,0),COLUMN(A$1))} -> 4 | C31: {=INDEX('HOTMAP-DATA'!$D$2:$G$1345,MATCH($A$28&$B$28&$A31,'HOTMAP-DATA'!$A$2:$A$1345&'HOTMAP-DATA'!$B$2:$B$1345&'HOTMAP-DATA'!$C$2:$C$1345,0),COLUMN(B$1))} -> 1 | D31: {=INDEX('HOTMAP-DATA'!$D$2:$G$1345,MATCH($A$28&$B$28&$A31,'HOTMAP-DATA'!$A$2:$A$1345&'HOTMAP-DATA'!$B$2:$B$1345&'HOTMAP-DATA'!$C$2:$C$1345,0),COLUMN(C$1))} -> 2 | E31: {=INDEX('HOTMAP-DATA'!$D$2:$G$1345,MATCH($A$28&$B$28&$A31,'HOTMAP-DATA'!$A$2:$A$1345&'HOTMAP-DATA'!$B$2:$B$1345&'HOTMAP-DATA'!$C$2:$C$1345,0),COLUMN(D$1))} -> 1 | F31: Standard Hours | G31: 2 | H31: =INT((ROW(A2)-1)/4)+1 -> 1 | I31: {=INDEX(B$30:B$57,$H31)=$G31} -> FALSE | J31: {=INDEX(C$30:C$57,$H31)=$G31} -> TRUE | K31: {=INDEX(D$30:D$57,$H31)=$G31} -> TRUE | L31: {=INDEX(E$30:E$57,$H31)=$G31} -> TRUE | M31: TRUE | N31: TRUE | O31: TRUE | P31: TRUE
A32: 3 | B32: {=INDEX('HOTMAP-DATA'!$D$2:$G$1345,MATCH($A$28&$B$28&$A32,'HOTMAP-DATA'!$A$2:$A$1345&'HOTMAP-DATA'!$B$2:$B$1345&'HOTMAP-DATA'!$C$2:$C$1345,0),COLUMN(A$1))} -> 1 | C32: {=INDEX('HOTMAP-DATA'!$D$2:$G$1345,MATCH($A$28&$B$28&$A32,'HOTMAP-DATA'!$A$2:$A$1345&'HOTMAP-DATA'!$B$2:$B$1345&'HOTMAP-DATA'!$C$2:$C$1345,0),COLUMN(B$1))} -> 1 | D32: {=INDEX('HOTMAP-DATA'!$D$2:$G$1345,MATCH($A$28&$B$28&$A32,'HOTMAP-DATA'!$A$2:$A$1345&'HOTMAP-DATA'!$B$2:$B$1345&'HOTMAP-DATA'!$C$2:$C$1345,0),COLUMN(C$1))} -> 1 | E32: {=INDEX('HOTMAP-DATA'!$D$2:$G$1345,MATCH($A$28&$B$28&$A32,'HOTMAP-DATA'!$A$2:$A$1345&'HOTMAP-DATA'!$B$2:$B$1345&'HOTMAP-DATA'!$C$2:$C$1345,0),COLUMN(D$1))} -> 3 | F32: Overtime | G32: 3 | H32: =INT((ROW(A3)-1)/4)+1 -> 1 | I32: {=INDEX(B$30:B$57,$H32)=$G32} -> TRUE | J32: {=INDEX(C$30:C$57,$H32)=$G32} -> FALSE | K32: {=INDEX(D$30:D$57,$H32)=$G32} -> FALSE | L32: {=INDEX(E$30:E$57,$H32)=$G32} -> FALSE | M32: TRUE | N32: TRUE | O32: TRUE | P32: TRUE
A33: 4 | B33: {=INDEX('HOTMAP-DATA'!$D$2:$G$1345,MATCH($A$28&$B$28&$A33,'HOTMAP-DATA'!$A$2:$A$1345&'HOTMAP-DATA'!$B$2:$B$1345&'HOTMAP-DATA'!$C$2:$C$1345,0),COLUMN(A$1))} -> 1 | C33: {=INDEX('HOTMAP-DATA'!$D$2:$G$1345,MATCH($A$28&$B$28&$A33,'HOTMAP-DATA'!$A$2:$A$1345&'HOTMAP-DATA'!$B$2:$B$1345&'HOTMAP-DATA'!$C$2:$C$1345,0),COLUMN(B$1))} -> 1 | D33: {=INDEX('HOTMAP-DATA'!$D$2:$G$1345,MATCH($A$28&$B$28&$A33,'HOTMAP-DATA'!$A$2:$A$1345&'HOTMAP-DATA'!$B$2:$B$1345&'HOTMAP-DATA'!$C$2:$C$1345,0),COLUMN(C$1))} -> 1 | E33: {=INDEX('HOTMAP-DATA'!$D$2:$G$1345,MATCH($A$28&$B$28&$A33,'HOTMAP-DATA'!$A$2:$A$1345&'HOTMAP-DATA'!$B$2:$B$1345&'HOTMAP-DATA'!$C$2:$C$1345,0),COLUMN(D$1))} -> 1 | F33: Excessive Overtime | G33: 4 | H33: =INT((ROW(A4)-1)/4)+1 -> 1 | I33: {=INDEX(B$30:B$57,$H33)=$G33} -> FALSE | J33: {=INDEX(C$30:C$57,$H33)=$G33} -> FALSE | K33: {=INDEX(D$30:D$57,$H33)=$G33} -> FALSE | L33: {=INDEX(E$30:E$57,$H33)=$G33} -> FALSE | M33: TRUE | N33: TRUE | O33: TRUE | P33: TRUE
A34: 5 | B34: {=INDEX('HOTMAP-DATA'!$D$2:$G$1345,MATCH($A$28&$B$28&$A34,'HOTMAP-DATA'!$A$2:$A$1345&'HOTMAP-DATA'!$B$2:$B$1345&'HOTMAP-DATA'!$C$2:$C$1345,0),COLUMN(A$1))} -> 4 | C34: {=INDEX('HOTMAP-DATA'!$D$2:$G$1345,MATCH($A$28&$B$28&$A34,'HOTMAP-DATA'!$A$2:$A$1345&'HOTMAP-DATA'!$B$2:$B$1345&'HOTMAP-DATA'!$C$2:$C$1345,0),COLUMN(B$1))} -> 2 | D34: {=INDEX('HOTMAP-DATA'!$D$2:$G$1345,MATCH($A$28&$B$28&$A34,'HOTMAP-DATA'!$A$2:$A$1345&'HOTMAP-DATA'!$B$2:$B$1345&'HOTMAP-DATA'!$C$2:$C$1345,0),COLUMN(C$1))} -> 4 | E34: {=INDEX('HOTMAP-DATA'!$D$2:$G$1345,MATCH($A$28&$B$28&$A34,'HOTMAP-DATA'!$A$2:$A$1345&'HOTMAP-DATA'!$B$2:$B$1345&'HOTMAP-DATA'!$C$2:$C$1345,0),COLUMN(D$1))} -> 3 | G34: 1 | H34: =INT((ROW(A5)-1)/4)+1 -> 2 | I34: {=INDEX(B$30:B$57,$H34)=$G34} -> FALSE | J34: {=INDEX(C$30:C$57,$H34)=$G34} -> TRUE | K34: {=INDEX(D$30:D$57,$H34)=$G34} -> FALSE | L34: {=INDEX(E$30:E$57,$H34)=$G34} -> TRUE | M34: TRUE | N34: TRUE | O34: TRUE | P34: TRUE
A35: 6 | B35: {=INDEX('HOTMAP-DATA'!$D$2:$G$1345,MATCH($A$28&$B$28&$A35,'HOTMAP-DATA'!$A$2:$A$1345&'HOTMAP-DATA'!$B$2:$B$1345&'HOTMAP-DATA'!$C$2:$C$1345,0),COLUMN(A$1))} -> 3 | C35: {=INDEX('HOTMAP-DATA'!$D$2:$G$1345,MATCH($A$28&$B$28&$A35,'HOTMAP-DATA'!$A$2:$A$1345&'HOTMAP-DATA'!$B$2:$B$1345&'HOTMAP-DATA'!$C$2:$C$1345,0),COLUMN(B$1))} -> 1 | D35: {=INDEX('HOTMAP-DATA'!$D$2:$G$1345,MATCH($A$28&$B$28&$A35,'HOTMAP-DATA'!$A$2:$A$1345&'HOTMAP-DATA'!$B$2:$B$1345&'HOTMAP-DATA'!$C$2:$C$1345,0),COLUMN(C$1))} -> 3 | E35: {=INDEX('HOTMAP-DATA'!$D$2:$G$1345,MATCH($A$28&$B$28&$A35,'HOTMAP-DATA'!$A$2:$A$1345&'HOTMAP-DATA'!$B$2:$B$1345&'HOTMAP-DATA'!$C$2:$C$1345,0),COLUMN(D$1))} -> 1 | G35: 2 | H35: =INT((ROW(A6)-1)/4)+1 -> 2 | I35: {=INDEX(B$30:B$57,$H35)=$G35} -> FALSE | J35: {=INDEX(C$30:C$57,$H35)=$G35} -> FALSE | K35: {=INDEX(D$30:D$57,$H35)=$G35} -> TRUE | L35: {=INDEX(E$30:E$57,$H35)=$G35} -> FALSE | M35: TRUE | N35: TRUE | O35: TRUE | P35: TRUE
A36: 7 | B36: {=INDEX('HOTMAP-DATA'!$D$2:$G$1345,MATCH($A$28&$B$28&$A36,'HOTMAP-DATA'!$A$2:$A$1345&'HOTMAP-DATA'!$B$2:$B$1345&'HOTMAP-DATA'!$C$2:$C$1345,0),COLUMN(A$1))} -> 4 | C36: {=INDEX('HOTMAP-DATA'!$D$2:$G$1345,MATCH($A$28&$B$28&$A36,'HOTMAP-DATA'!$A$2:$A$1345&'HOTMAP-DATA'!$B$2:$B$1345&'HOTMAP-DATA'!$C$2:$C$1345,0),COLUMN(B$1))} -> 1 | D36: {=INDEX('HOTMAP-DATA'!$D$2:$G$1345,MATCH($A$28&$B$28&$A36,'HOTMAP-DATA'!$A$2:$A$1345&'HOTMAP-DATA'!$B$2:$B$1345&'HOTMAP-DATA'!$C$2:$C$1345,0),COLUMN(C$1))} -> 3 | E36: {=INDEX('HOTMAP-DATA'!$D$2:$G$1345,MATCH($A$28&$B$28&$A36,'HOTMAP-DATA'!$A$2:$A$1345&'HOTMAP-DATA'!$B$2:$B$1345&'HOTMAP-DATA'!$C$2:$C$1345,0),COLUMN(D$1))} -> 2 | G36: 3 | H36: =INT((ROW(A7)-1)/4)+1 -> 2 | I36: {=INDEX(B$30:B$57,$H36)=$G36} -> FALSE | J36: {=INDEX(C$30:C$57,$H36)=$G36} -> FALSE | K36: {=INDEX(D$30:D$57,$H36)=$G36} -> FALSE | L36: {=INDEX(E$30:E$57,$H36)=$G36} -> FALSE | M36: TRUE | N36: TRUE | O36: TRUE | P36: TRUE
A37: 8 | B37: {=INDEX('HOTMAP-DATA'!$D$2:$G$1345,MATCH($A$28&$B$28&$A37,'HOTMAP-DATA'!$A$2:$A$1345&'HOTMAP-DATA'!$B$2:$B$1345&'HOTMAP-DATA'!$C$2:$C$1345,0),COLUMN(A$1))} -> 3 | C37: {=INDEX('HOTMAP-DATA'!$D$2:$G$1345,MATCH($A$28&$B$28&$A37,'HOTMAP-DATA'!$A$2:$A$1345&'HOTMAP-DATA'!$B$2:$B$1345&'HOTMAP-DATA'!$C$2:$C$1345,0),COLUMN(B$1))} -> 3 | D37: {=INDEX('HOTMAP-DATA'!$D$2:$G$1345,MATCH($A$28&$B$28&$A37,'HOTMAP-DATA'!$A$2:$A$1345&'HOTMAP-DATA'!$B$2:$B$1345&'HOTMAP-DATA'!$C$2:$C$1345,0),COLUMN(C$1))} -> 2 | E37: {=INDEX('HOTMAP-DATA'!$D$2:$G$1345,MATCH($A$28&$B$28&$A37,'HOTMAP-DATA'!$A$2:$A$1345&'HOTMAP-DATA'!$B$2:$B$1345&'HOTMAP-DATA'!$C$2:$C$1345,0),COLUMN(D$1))} -> 1 | G37: 4 | H37: =INT((ROW(A8)-1)/4)+1 -> 2 | I37: {=INDEX(B$30:B$57,$H37)=$G37} -> TRUE | J37: {=INDEX(C$30:C$57,$H37)=$G37} -> FALSE | K37: {=INDEX(D$30:D$57,$H37)=$G37} -> FALSE | L37: {=INDEX(E$30:E$57,$H37)=$G37} -> FALSE | M37: TRUE | N37: TRUE | O37: TRUE | P37: TRUE
A38: 9 | B38: {=INDEX('HOTMAP-DATA'!$D$2:$G$1345,MATCH($A$28&$B$28&$A38,'HOTMAP-DATA'!$A$2:$A$1345&'HOTMAP-DATA'!$B$2:$B$1345&'HOTMAP-DATA'!$C$2:$C$1345,0),COLUMN(A$1))} -> 1 | C38: {=INDEX('HOTMAP-DATA'!$D$2:$G$1345,MATCH($A$28&$B$28&$A38,'HOTMAP-DATA'!$A$2:$A$1345&'HOTMAP-DATA'!$B$2:$B$1345&'HOTMAP-DATA'!$C$2:$C$1345,0),COLUMN(B$1))} -> 1 | D38: {=INDEX('HOTMAP-DATA'!$D$2:$G$1345,MATCH($A$28&$B$28&$A38,'HOTMAP-DATA'!$A$2:$A$1345&'HOTMAP-DATA'!$B$2:$B$1345&'HOTMAP-DATA'!$C$2:$C$1345,0),COLUMN(C$1))} -> 1 | E38: {=INDEX('HOTMAP-DATA'!$D$2:$G$1345,MATCH($A$28&$B$28&$A38,'HOTMAP-DATA'!$A$2:$A$1345&'HOTMAP-DATA'!$B$2:$B$1345&'HOTMAP-DATA'!$C$2:$C$1345,0),COLUMN(D$1))} -> 3 | G38: 1 | H38: =INT((ROW(A9)-1)/4)+1 -> 3 | I38: {=INDEX(B$30:B$57,$H38)=$G38} -> TRUE | J38: {=INDEX(C$30:C$57,$H38)=$G38} -> TRUE | K38: {=INDEX(D$30:D$57,$H38)=$G38} -> TRUE | L38: {=INDEX(E$30:E$57,$H38)=$G38} -> FALSE | M38: TRUE | N38: TRUE | O38: TRUE | P38: TRUE
A39: 10 | B39: {=INDEX('HOTMAP-DATA'!$D$2:$G$1345,MATCH($A$28&$B$28&$A39,'HOTMAP-DATA'!$A$2:$A$1345&'HOTMAP-DATA'!$B$2:$B$1345&'HOTMAP-DATA'!$C$2:$C$1345,0),COLUMN(A$1))} -> 2 | C39: {=INDEX('HOTMAP-DATA'!$D$2:$G$1345,MATCH($A$28&$B$28&$A39,'HOTMAP-DATA'!$A$2:$A$1345&'HOTMAP-DATA'!$B$2:$B$1345&'HOTMAP-DATA'!$C$2:$C$1345,0),COLUMN(B$1))} -> 4 | D39: {=INDEX('HOTMAP-DATA'!$D$2:$G$1345,MATCH($A$28&$B$28&$A39,'HOTMAP-DATA'!$A$2:$A$1345&'HOTMAP-DATA'!$B$2:$B$1345&'HOTMAP-DATA'!$C$2:$C$1345,0),COLUMN(C$1))} -> 1 | E39: {=INDEX('HOTMAP-DATA'!$D$2:$G$1345,MATCH($A$28&$B$28&$A39,'HOTMAP-DATA'!$A$2:$A$1345&'HOTMAP-DATA'!$B$2:$B$1345&'HOTMAP-DATA'!$C$2:$C$1345,0),COLUMN(D$1))} -> 1 | G39: 2 | H39: =INT((ROW(A10)-1)/4)+1 -> 3 | I39: {=INDEX(B$30:B$57,$H39)=$G39} -> FALSE | J39: {=INDEX(C$30:C$57,$H39)=$G39} -> FALSE | K39: {=INDEX(D$30:D$57,$H39)=$G39} -> FALSE | L39: {=INDEX(E$30:E$57,$H39)=$G39} -> FALSE | M39: TRUE | N39: TRUE | O39: TRUE | P39: TRUE
A40: 11 | B40: {=INDEX('HOTMAP-DATA'!$D$2:$G$1345,MATCH($A$28&$B$28&$A40,'HOTMAP-DATA'!$A$2:$A$1345&'HOTMAP-DATA'!$B$2:$B$1345&'HOTMAP-DATA'!$C$2:$C$1345,0),COLUMN(A$1))} -> 2 | C40: {=INDEX('HOTMAP-DATA'!$D$2:$G$1345,MATCH($A$28&$B$28&$A40,'HOTMAP-DATA'!$A$2:$A$1345&'HOTMAP-DATA'!$B$2:$B$1345&'HOTMAP-DATA'!$C$2:$C$1345,0),COLUMN(B$1))} -> 1 | D40: {=INDEX('HOTMAP-DATA'!$D$2:$G$1345,MATCH($A$28&$B$28&$A40,'HOTMAP-DATA'!$A$2:$A$1345&'HOTMAP-DATA'!$B$2:$B$1345&'HOTMAP-DATA'!$C$2:$C$1345,0),COLUMN(C$1))} -> 2 | E40: {=INDEX('HOTMAP-DATA'!$D$2:$G$1345,MATCH($A$28&$B$28&$A40,'HOTMAP-DATA'!$A$2:$A$1345&'HOTMAP-DATA'!$B$2:$B$1345&'HOTMAP-DATA'!$C$2:$C$1345,0),COLUMN(D$1))} -> 2 | G40: 3 | H40: =INT((ROW(A11)-1)/4)+1 -> 3 | I40: {=INDEX(B$30:B$57,$H40)=$G40} -> FALSE | J40: {=INDEX(C$30:C$57,$H40)=$G40} -> FALSE | K40: {=INDEX(D$30:D$57,$H40)=$G40} -> FALSE | L40: {=INDEX(E$30:E$57,$H40)=$G40} -> TRUE | M40: TRUE | N40: TRUE | O40: TRUE | P40: TRUE
...

Sheet Control
A3: Row Labels | B3: Sum of Payroll | C3: Sum of Actual | D3: Sum of Management | E3: Sum of Administrative Staff | F3: Sum of Sales Department | G3: Sum of Production Department | H3: Sum of Logistics Department | I3: Average of Standard Hours | J3: Average of A | K3: Average of B | L3: Average of C | M3: Average of D | N3: Average of E | O3: Average of A2 | P3: Average of B2 | Q3: Average of C2 | R3: Average of D2 | S3: Average of E2 | T3: Average of Head Office | U3: Average of Regional Offices | V3: Average of Regional Branches | W3: Average of Remote Employees | X3: Average of Outsourcing | Y3: Sum of Employee1 | Z3: Sum of Employee2 | AA3: Sum of Employee3 | AB3: Sum of Employee4 | AC3: Sum of Employee5 | AD3: Sum of Employee1BS | AE3: Sum of Employee2BS | AF3: Sum of Employee3BS | AG3: Sum of Employee4BS | AH3: Sum of Employee5BS
A4: OCT | B4: 118840 | C4: 80000 | D4: 60760 | E4: 50950 | F4: 53140 | G4: 38170 | H4: 34660 | I4: 0.72 | J4: 0.62 | K4: 0.87 | L4: 1.18 | M4: 0.38 | N4: 0.36 | O4: 0.35 | P4: 0.45 | Q4: 0.63 | R4: 0.61 | S4: 0.53 | T4: 0.28 | U4: 0.21 | V4: 0.13 | W4: 0.05 | X4: 0.33 | Y4: 9700 | Z4: 2900 | AA4: 4600 | AB4: 5300 | AC4: 6000 | AD4: 3500 | AE4: 6500 | AF4: 2400 | AG4: 5900 | AH4: 3000
A5: Grand Total | B5: 118840 | C5: 80000 | D5: 60760 | E5: 50950 | F5: 53140 | G5: 38170 | H5: 34660 | I5: 0.72 | J5: 0.62 | K5: 0.87 | L5: 1.18 | M5: 0.38 | N5: 0.36 | O5: 0.35 | P5: 0.45 | Q5: 0.63 | R5: 0.61 | S5: 0.53 | T5: 0.28 | U5: 0.21 | V5: 0.13 | W5: 0.05 | X5: 0.33 | Y5: 9700 | Z5: 2900 | AA5: 4600 | AB5: 5300 | AC5: 6000 | AD5: 3500 | AE5: 6500 | AF5: 2400 | AG5: 5900 | AH5: 3000
A20: Row Labels | B20: Sum of Payroll | C20: Sum of Annual Payroll Plan | D20: Sum of Forecast | E20: Sum of Actual
A21: JAN | B21: 53818 | C21: 60000 | D21: 50000 | E21: 40000
A22: FEB | B22: 76798 | C22: 60000 | D22: 40000 | E22: 50000
A23: MAR | B23: 78380 | C23: 60000 | D23: 50000 | E23: 35000
A24: APR | B24: 80403 | C24: 60000 | D24: 45000 | E24: 55000
A25: MAY | B25: 110090 | C25: 60000 | D25: 70000 | E25: 60000
A26: JUN | B26: 127270 | C26: 60000 | D26: 60000 | E26: 80000
A27: JUL | B27: 127090 | C27: 60000 | D27: 80000 | E27: 95000
A28: AUG | B28: 126645 | C28: 60000 | D28: 70000 | E28: 90000
A29: SEP | B29: 121425 | C29: 60000 | D29: 80000 | E29: 70000
A30: OCT | B30: 118840 | C30: 60000 | D30: 100000 | E30: 80000
A31: NOV | B31: 98685 | C31: 60000 | D31: 95000 | E31: 60000
A32: DEC | B32: 98395 | C32: 60000 | D32: 80000 | E32: 50000
A33: Grand Total | B33: 1217839 | C33: 720000 | D33: 820000 | E33: 765000
A36: Row Labels
A37: 2025
A38: Grand Total

Sheet Data
T1: Employee Performance | AD1: Payroll Forecast | AR1: Top 5 Employees Payroll
C2: Employee Categories | H2: Payroll Cost Breakdown | K2: Payroll Fund | M2: Payroll WHR | O2: PDL | T2: KPI | Y2: MoM | AD2: Planned Payroll | AK2: Actual Payroll | AR2: Bonus | AW2: Base Salary
A3: Year | B3: Month | C3: Management | D3: Administrative Staff | E3: Sales Department | F3: Production Department | G3: Logistics Department | H3: Basic | I3: Bonuses | J3: Payroll Taxes | K3: Payroll | L3: Annual Payroll Plan | M3: Standard Hours | N3: Actual Hours | O3: Head Office | P3: Regional Offices | Q3: Regional Branches | R3: Remote Employees | S3: Outsourcing | T3: A | U3: B | V3: C | W3: D | X3: E | Y3: A2 | Z3: B2 | AA3: C2 | AB3: D2 | AC3: E2 | AD3: SU | AE3: MO | AF3: TU | AG3: WE | AH3: TH | AI3: FR | AJ3: SA | AK3: SU2 | AL3: MO2 | AM3: TU2 | AN3: WE2 | AO3: TH2 | AP3: FR2 | AQ3: SA2 | AR3: Employee1 | AS3: Employee2 | AT3: Employee3 | AU3: Employee4 | AV3: Employee5 | AW3: Employee1BS | AX3: Employee2BS | AY3: Employee3BS | AZ3: Employee4BS | BA3: Employee5BS | BB3: Forecast | BC3: Actual
A4: 2025 | B4: JAN | C4: 28340 | D4: 18130 | E4: 20185 | F4: 20270 | G4: 20710 | H4: 0.4 | I4: 0.41 | J4: 0.19 | K4: 53818 | L4: 60000 | M4: 0.33 | N4: 0.71 | O4: 0.26 | P4: 0.23 | Q4: 0.12 | R4: 0.11 | S4: 0.28 | T4: 1.08 | U4: 0.47 | V4: 1.34 | W4: 0.47 | X4: 0.5 | Y4: 0.46 | Z4: 0.39 | AA4: 0.59 | AB4: 0.48 | AC4: 0.7 | AD4: 59867 | AE4: 29705 | AF4: 695 | AG4: 88522 | AH4: 10928 | AI4: 15996 | AJ4: 34287 | AK4: 33107 | AL4: 10047 | AM4: 37625 | AN4: 42413 | AO4: 37885 | AP4: 27649 | AQ4: 31454 | AR4: 5200 | AS4: 3100 | AT4: 6300 | AU4: 6000 | AV4: 6600 | AW4: 7300 | AX4: 4300 | AY4: 4500 | AZ4: 4100 | BA4: 4100 | BB4: 50000 | BC4: 40000
A5: 2025 | B5: FEB | C5: 33090 | D5: 19480 | E5: 23855 | F5: 43990 | G5: 33180 | H5: 0.37 | I5: 0.43 | J5: 0.2 | K5: 76798 | L5: 60000 | M5: 0.17 | N5: 0.5 | O5: 0.34 | P5: 0.23 | Q5: 0.12 | R5: 0.12 | S5: 0.19 | T5: 0.91 | U5: 0.54 | V5: 1.32 | W5: 0.52 | X5: 1.13 | Y5: 0.48 | Z5: 0.56 | AA5: 0.57 | AB5: 0.38 | AC5: 0.64 | AD5: 10456 | AE5: 27396 | AF5: 49816 | AG5: 34348 | AH5: 38205 | AI5: 45492 | AJ5: 34287 | AK5: 42731 | AL5: 41459 | AM5: 21075 | AN5: 31812 | AO5: 21932 | AP5: 38151 | AQ5: 32860 | AR5: 9300 | AS5: 2900 | AT5: 3800 | AU5: 4800 | AV5: 6100 | AW5: 3600 | AX5: 5700 | AY5: 5400 | AZ5: 3300 | BA5: 3700 | BB5: 40000 | BC5: 50000
A6: 2025 | B6: MAR | C6: 31685 | D6: 33955 | E6: 27270 | F6: 34630 | G6: 29220 | H6: 0.35 | I6: 0.48 | J6: 0.17 | K6: 78380 | L6: 60000 | M6: 0.64 | N6: 0.64 | O6: 0.28 | P6: 0.21 | Q6: 0.16 | R6: 0.11 | S6: 0.24 | T6: 0.91 | U6: 0.35 | V6: 1.21 | W6: 0.98 | X6: 0.81 | Y6: 0.57 | Z6: 0.45 | AA6: 0.61 | AB6: 0.38 | AC6: 0.26 | AD6: 24662 | AE6: 37454 | AF6: 37903 | AG6: 47190 | AH6: 44974 | AI6: 13532 | AJ6: 34285 | AK6: 53313 | AL6: 4272 | AM6: 27492 | AN6: 43898 | AO6: 38795 | AP6: 42932 | AQ6: 35118 | AR6: 7000 | AS6: 3000 | AT6: 7000 | AU6: 8300 | AV6: 2800 | AW6: 3100 | AX6: 5500 | AY6: 4400 | AZ6: 3500 | BA6: 5200 | BB6: 50000 | BC6: 35000
A7: 2025 | B7: APR | C7: 36840 | D7: 23340 | E7: 36425 | F7: 33470 | G7: 30730 | H7: 0.36 | I7: 0.45 | J7: 0.19 | K7: 80403 | L7: 60000 | M7: 0.4 | N7: 0.24 | O7: 0.31 | P7: 0.3 | Q7: 0.12 | R7: 0.07 | S7: 0.2 | T7: 1.24 | U7: 1.06 | V7: 1.08 | W7: 0.91 | X7: 1.07 | Y7: 0.26 | Z7: 0.31 | AA7: 0.56 | AB7: 0.7 | AC7: 0.3 | AD7: 28363 | AE7: 32559 | AF7: 2859 | AG7: 44682 | AH7: 89111 | AI7: 8141 | AJ7: 34285 | AK7: 19542 | AL7: 42659 | AM7: 40003 | AN7: 20115 | AO7: 40007 | AP7: 40200 | AQ7: 33754 | AR7: 6700 | AS7: 5700 | AT7: 4500 | AU7: 5000 | AV7: 2700 | AW7: 5900 | AX7: 6100 | AY7: 5500 | AZ7: 3500 | BA7: 6100 | BB7: 45000 | BC7: 55000
A8: 2025 | B8: MAY | C8: 64590 | D8: 41860 | E8: 49940 | F8: 34330 | G8: 29460 | H8: 0.36 | I8: 0.4 | J8: 0.24 | K8: 110090 | L8: 60000 | M8: 0.2 | N8: 0.25 | O8: 0.31 | P8: 0.22 | Q8: 0.13 | R8: 0.14 | S8: 0.2 | T8: 0.94 | U8: 0.99 | V8: 0.77 | W8: 1.02 | X8: 0.76 | Y8: 0.3 | Z8: 0.59 | AA8: 0.31 | AB8: 0.73 | AC8: 0.55 | AD8: 6097 | AE8: 46394 | AF8: 56704 | AG8: 18425 | AH8: 17854 | AI8: 60241 | AJ8: 34285 | AK8: 48037 | AL8: 41586 | AM8: 31950 | AN8: 44847 | AO8: 8193 | AP8: 43737 | AQ8: 36390 | AR8: 8900 | AS8: 3400 | AT8: 2900 | AU8: 4000 | AV8: 4500 | AW8: 3500 | AX8: 5400 | AY8: 4200 | AZ8: 2900 | BA8: 6600 | BB8: 70000 | BC8: 60000
A9: 2025 | B9: JUN | C9: 76530 | D9: 54200 | E9: 45950 | F9: 42900 | G9: 34960 | H9: 0.38 | I9: 0.5 | J9: 0.12 | K9: 127270 | L9: 60000 | M9: 0.44 | N9: 0.69 | O9: 0.35 | P9: 0.21 | Q9: 0.16 | R9: 0.08 | S9: 0.2 | T9: 1.1 | U9: 1.25 | V9: 0.85 | W9: 1.31 | X9: 0.94 | Y9: 0.59 | Z9: 0.56 | AA9: 0.7 | AB9: 0.73 | AC9: 0.39 | AD9: 23965 | AE9: 47071 | AF9: 30345 | AG9: 36671 | AH9: 54945 | AI9: 12717 | AJ9: 34286 | AK9: 31971 | AL9: 45318 | AM9: 39555 | AN9: 45223 | AO9: 16585 | AP9: 43065 | AQ9: 36953 | AR9: 6200 | AS9: 3200 | AT9: 4200 | AU9: 3100 | AV9: 4900 | AW9: 4000 | AX9: 4600 | AY9: 5500 | AZ9: 5200 | BA9: 3800 | BB9: 60000 | BC9: 80000
A10: 2025 | B10: JUL | C10: 84020 | D10: 53040 | E10: 54240 | F10: 32710 | G10: 30170 | H10: 0.37 | I10: 0.48 | J10: 0.15 | K10: 127090 | L10: 60000 | M10: 0.24 | N10: 0.41 | O10: 0.31 | P10: 0.2 | Q10: 0.16 | R10: 0.11 | S10: 0.22 | T10: 0.37 | U10: 0.46 | V10: 0.68 | W10: 1.24 | X10: 0.88 | Y10: 0.52 | Z10: 0.61 | AA10: 0.34 | AB10: 0.48 | AC10: 0.33 | AD10: 33952 | AE10: 59758 | AF10: 23186 | AG10: 5088 | AH10: 15481 | AI10: 68250 | AJ10: 34285 | AK10: 73225 | AL10: 82752 | AM10: 6957 | AN10: 11539 | AO10: 18644 | AP10: 7222 | AQ10: 33391 | AR10: 4900 | AS10: 4800 | AT10: 2300 | AU10: 2700 | AV10: 4700 | AW10: 4100 | AX10: 3400 | AY10: 4700 | AZ10: 4800 | BA10: 2500 | BB10: 80000 | BC10: 95000
A11: 2025 | B11: AUG | C11: 84170 | D11: 49190 | E11: 50140 | F11: 41480 | G11: 28310 | H11: 0.37 | I11: 0.44 | J11: 0.19 | K11: 126645 | L11: 60000 | M11: 0.75 | N11: 0.6 | O11: 0.34 | P11: 0.26 | Q11: 0.17 | R11: 0.12 | S11: 0.11 | T11: 0.53 | U11: 1.05 | V11: 0.59 | W11: 0.44 | X11: 0.64 | Y11: 0.51 | Z11: 0.29 | AA11: 0.3 | AB11: 0.41 | AC11: 0.32 | AD11: 44592 | AE11: 48774 | AF11: 27775 | AG11: 25626 | AH11: 32862 | AI11: 26085 | AJ11: 34286 | AK11: 56058 | AL11: 49917 | AM11: 48765 | AN11: 42341 | AO11: 4345 | AP11: 13391 | AQ11: 35803 | AR11: 7900 | AS11: 5400 | AT11: 5800 | AU11: 4800 | AV11: 3300 | AW11: 4300 | AX11: 5100 | AY11: 3000 | AZ11: 2200 | BA11: 7000 | BB11: 70000 | BC11: 90000
A12: 2025 | B12: SEP | C12: 78630 | D12: 41370 | E12: 53770 | F12: 37090 | G12: 31990 | H12: 0.37 | I12: 0.44 | J12: 0.19 | K12: 121425 | L12: 60000 | M12: 0.73 | N12: 0.5 | O12: 0.33 | P12: 0.21 | Q12: 0.17 | R12: 0.11 | S12: 0.18 | T12: 0.74 | U12: 0.45 | V12: 1.24 | W12: 0.38 | X12: 1.06 | Y12: 0.72 | Z12: 0.42 | AA12: 0.38 | AB12: 0.74 | AC12: 0.49 | AD12: 41608 | AE12: 38687 | AF12: 32685 | AG12: 40758 | AH12: 15259 | AI12: 36718 | AJ12: 34285 | AK12: 17916 | AL12: 14439 | AM12: 6383 | AN12: 47775 | AO12: 68781 | AP12: 62626 | AQ12: 36320 | AR12: 6900 | AS12: 5400 | AT12: 3400 | AU12: 4800 | AV12: 4500 | AW12: 4200 | AX12: 5400 | AY12: 6000 | AZ12: 5200 | BA12: 5600 | BB12: 80000 | BC12: 70000
A13: 2025 | B13: OCT | C13: 60760 | D13: 50950 | E13: 53140 | F13: 38170 | G13: 34660 | H13: 0.39 | I13: 0.54 | J13: 0.07 | K13: 118840 | L13: 60000 | M13: 0.72 | N13: 0.47 | O13: 0.28 | P13: 0.21 | Q13: 0.13 | R13: 0.05 | S13: 0.33 | T13: 0.62 | U13: 0.87 | V13: 1.18 | W13: 0.38 | X13: 0.36 | Y13: 0.35 | Z13: 0.45 | AA13: 0.63 | AB13: 0.61 | AC13: 0.53 | AD13: 55756 | AE13: 73802 | AF13: 10991 | AG13: 7018 | AH13: 46491 | AI13: 11657 | AJ13: 34285 | AK13: 30546 | AL13: 14673 | AM13: 18630 | AN13: 49112 | AO13: 49019 | AP13: 29146 | AQ13: 31854 | AR13: 9700 | AS13: 2900 | AT13: 4600 | AU13: 5300 | AV13: 6000 | AW13: 3500 | AX13: 6500 | AY13: 2400 | AZ13: 5900 | BA13: 3000 | BB13: 100000 | BC13: 80000
A14: 2025 | B14: NOV | C14: 44165 | D14: 37275 | E14: 37120 | F14: 44480 | G14: 34330 | H14: 0.38 | I14: 0.45 | J14: 0.17 | K14: 98685 | L14: 60000 | M14: 0.73 | N14: 0.75 | O14: 0.25 | P14: 0.22 | Q14: 0.15 | R14: 0.07 | S14: 0.31 | T14: 0.63 | U14: 0.97 | V14: 0.82 | W14: 1.07 | X14: 0.72 | Y14: 0.61 | Z14: 0.4 | AA14: 0.68 | AB14: 0.39 | AC14: 0.63 | AD14: 41610 | AE14: 2642 | AF14: 48284 | AG14: 17938 | AH14: 48687 | AI14: 46554 | AJ14: 34285 | AK14: 58809 | AL14: 44756 | AM14: 6109 | AN14: 24468 | AO14: 33398 | AP14: 49565 | AQ14: 36185 | AR14: 5400 | AS14: 4700 | AT14: 3500 | AU14: 6000 | AV14: 4900 | AW14: 4800 | AX14: 2600 | AY14: 7500 | AZ14: 4300 | BA14: 6200 | BB14: 95000 | BC14: 60000
A15: 2025 | B15: DEC | C15: 21930 | D15: 14850 | E15: 11285 | F15: 27630 | G15: 22700 | H15: 0.4 | I15: 0.54 | J15: 0.06 | K15: 98395 | L15: 60000 | M15: 0.36 | N15: 0.28 | O15: 0.3 | P15: 0.24 | Q15: 0.15 | R15: 0.15 | S15: 0.16 | T15: 0.71 | U15: 0.8 | V15: 0.57 | W15: 0.39 | X15: 0.61 | Y15: 0.72 | Z15: 0.58 | AA15: 0.65 | AB15: 0.49 | AC15: 0.57 | AD15: 45691 | AE15: 60215 | AF15: 19839 | AG15: 13621 | AH15: 59767 | AI15: 6581 | AJ15: 34286 | AK15: 42222 | AL15: 4090 | AM15: 39033 | AN15: 58269 | AO15: 68482 | AP15: 58702 | AQ15: 45132 | AR15: 8700 | AS15: 3600 | AT15: 4700 | AU15: 6500 | AV15: 4500 | AW15: 4900 | AX15: 4700 | AY15: 6700 | AZ15: 3600 | BA15: 3200 | BB15: 80000 | BC15: 50000
... A51: 2028 | B51: DEC | C51: 62575 | D51: 70425 | E51: 52725 | F51: 79400 | G51: 66650 | H51: 0.36 | I51: 0.48 | J51: 0.16 | K51: 133700 | L51: 100000 | M51: 0.22 | N51: 0.45 | O51: 0.33 | P51: 0.25 | Q51: 0.15 | R51: 0.05 | S51: 0.22 | T51: 1.04 | U51: 0.95 | V51: 0.63 | W51: 0.55 | X51: 1.26 | Y51: 0.63 | Z51: 0.69 | AA51: 0.6 | AB51: 0.28 | AC51: 0.29 | AD51: 62859 | AE51: 117796 | AF51: 118263 | AG51: 667 | AH51: 74945 | AI51: 54042 | AJ51: 71428 | AK51: 52446 | AL51: 92341 | AM51: 76327 | AN51: 33912 | AO51: 95373 | AP51: 93173 | AQ51: 73928 | AR51: 3100 | AS51: 3900 | AT51: 7100 | AU51: 4600 | AV51: 4800 | AW51: 7400 | AX51: 4300 | AY51: 4400 | AZ51: 5800 | BA51: 4300 | BB51: 92000 | BC51: 80000

Sheet HOTMAP-DATA
A1: Year | B1: Month | C1: Day | D1: Shift 1 | E1: Shift 2 | F1: Shift 3 | G1: Shift 4
A2: 2025 | B2: JAN | C2: 1 | D2: 2 | E2: 1 | F2: 2 | G2: 4
A3: 2025 | B3: JAN | C3: 2 | D3: 1 | E3: 2 | F3: 1 | G3: 1
A4: 2025 | B4: JAN | C4: 3 | D4: 1 | E4: 2 | F4: 4 | G4: 1
A5: 2025 | B5: JAN | C5: 4 | D5: 3 | E5: 2 | F5: 1 | G5: 3
A6: 2025 | B6: JAN | C6: 5 | D6: 1 | E6: 2 | F6: 2 | G6: 3
A7: 2025 | B7: JAN | C7: 6 | D7: 1 | E7: 2 | F7: 2 | G7: 1
A8: 2025 | B8: JAN | C8: 7 | D8: 4 | E8: 2 | F8: 3 | G8: 1
A9: 2025 | B9: JAN | C9: 8 | D9: 1 | E9: 2 | F9: 3 | G9: 3
A10: 2025 | B10: JAN | C10: 9 | D10: 1 | E10: 2 | F10: 3 | G10: 3
A11: 2025 | B11: JAN | C11: 10 | D11: 1 | E11: 2 | F11: 3 | G11: 4
A12: 2025 | B12: JAN | C12: 11 | D12: 3 | E12: 2 | F12: 3 | G12: 4
A13: 2025 | B13: JAN | C13: 12 | D13: 1 | E13: 4 | F13: 3 | G13: 3
... A1345: 2028 | B1345: DEC | C1345: 28 | D1345: 2 | E1345: 1 | F1345: 1 | G1345: 3

Sheet Resources
B1: Colors | C1: Position | D1: Angle | E1: Transparency | G1: Shadow | O1: $#,##0;-$#,##0;0 | R1: [>=1000]0,"k";[<=-1000]-0,"k";0
B2: #0D5682
B3: #0C1321
A4: Line | B4: #78DCF4
A6: Line | B6: #4E95D9
B7: #0C203A
B8: #008AF2
B9: #0F4672
A11: Line | B11: #3B9BD1
A12: Line | B12: #008AF2
