Workbook
Name Slicer_Month: #N/A
Name Slicer_Week_Day: #N/A
Name Slicer_Year: #N/A

Sheet DASHBOARD

Sheet DASHBOARD Light

Sheet Revenue vs Expenses

Sheet Revenue vs Expenses Light

Sheet Sales Closed

Sheet Sales Closed Light

Sheet Products

Sheet Products Light

Sheet ROI

Sheet ROI Light

Sheet Processing
A1: Investments vs Sales Volume | B1: Investments | C1: Sales Volume | D1: Cursor I | E1: Cursor S | F1: indent | H1: Week Day | I1: Day | J1: Sales Closed | L1: indent | M1: Marker | N1: Labels | P1: Sales Profitability Dashboard
A2: JAN | B2: =GETPIVOTDATA(""&B$1,Control!$A$20,"Month",""&$A2) -> 28026 | C2: =GETPIVOTDATA(""&C$1,Control!$A$20,"Month",""&$A2) -> 33543 | D2: =IFERROR(GETPIVOTDATA(""&B$1,Control!$A$3,"Month",""&$A2),NA()) -> 28026 | E2: =IFERROR(GETPIVOTDATA(""&C$1,Control!$A$3,"Month",""&$A2),NA()) -> 33543 | F2: =$F$14 -> 1545.76 | H2: Monday | I2: MON | J2: =GETPIVOTDATA(""&I2,Control!$A$3) -> 1511 | K2: =IF(ISNUMBER(MATCH(H2,Control!$A$43:$A$47,0)),Processing!J2,NA()) -> #N/A | L2: =$L$7 -> 229.64 | M2: =L2+K2 -> #N/A | N2: =IF(ISNA(K2),"",IF(K2<1000,K2,ROUND(K2/1000,1)&"K"))
A3: FEB | B3: =GETPIVOTDATA(""&B$1,Control!$A$20,"Month",""&$A3) -> 36152 | C3: =GETPIVOTDATA(""&C$1,Control!$A$20,"Month",""&$A3) -> 33555 | D3: =IFERROR(GETPIVOTDATA(""&B$1,Control!$A$3,"Month",""&$A3),NA()) -> #N/A | E3: =IFERROR(GETPIVOTDATA(""&C$1,Control!$A$3,"Month",""&$A3),NA()) -> #N/A | F3: =$F$14 -> 1545.76 | H3: Tuesday | I3: TUE | J3: =GETPIVOTDATA(""&I3,Control!$A$3) -> 5603 | K3: =IF(ISNUMBER(MATCH(H3,Control!$A$43:$A$47,0)),Processing!J3,NA()) -> 5603 | L3: =$L$7 -> 229.64 | M3: =L3+K3 -> 5832.64 | N3: =IF(ISNA(K3),"",IF(K3<1000,K3,ROUND(K3/1000,1)&"K")) -> 5.6K | P3: =IF(COUNTA(Control!A4:A6)=2,INDEX(L20:L31,MATCH(Control!A4,Processing!A2:A13,0)),"") -> JANUARY | Q3: =IF(COUNTA(Control!A36:A38)=2,Control!A36,"") -> 2024
A4: MAR | B4: =GETPIVOTDATA(""&B$1,Control!$A$20,"Month",""&$A4) -> 38644 | C4: =GETPIVOTDATA(""&C$1,Control!$A$20,"Month",""&$A4) -> 38370 | D4: =IFERROR(GETPIVOTDATA(""&B$1,Control!$A$3,"Month",""&$A4),NA()) -> #N/A | E4: =IFERROR(GETPIVOTDATA(""&C$1,Control!$A$3,"Month",""&$A4),NA()) -> #N/A | F4: =$F$14 -> 1545.76 | H4: Wednesday | I4: WED | J4: =GETPIVOTDATA(""&I4,Control!$A$3) -> 5741 | K4: =IF(ISNUMBER(MATCH(H4,Control!$A$43:$A$47,0)),Processing!J4,NA()) -> 5741 | L4: =$L$7 -> 229.64 | M4: =L4+K4 -> 5970.64 | N4: =IF(ISNA(K4),"",IF(K4<1000,K4,ROUND(K4/1000,1)&"K")) -> 5.7K
A5: APR | B5: =GETPIVOTDATA(""&B$1,Control!$A$20,"Month",""&$A5) -> 35469 | C5: =GETPIVOTDATA(""&C$1,Control!$A$20,"Month",""&$A5) -> 44242 | D5: =IFERROR(GETPIVOTDATA(""&B$1,Control!$A$3,"Month",""&$A5),NA()) -> #N/A | E5: =IFERROR(GETPIVOTDATA(""&C$1,Control!$A$3,"Month",""&$A5),NA()) -> #N/A | F5: =$F$14 -> 1545.76 | H5: Thursday | I5: THU | J5: =GETPIVOTDATA(""&I5,Control!$A$3) -> 2858 | K5: =IF(ISNUMBER(MATCH(H5,Control!$A$43:$A$47,0)),Processing!J5,NA()) -> 2858 | L5: =$L$7 -> 229.64 | M5: =L5+K5 -> 3087.64 | N5: =IF(ISNA(K5),"",IF(K5<1000,K5,ROUND(K5/1000,1)&"K")) -> 2.9K
A6: MAY | B6: =GETPIVOTDATA(""&B$1,Control!$A$20,"Month",""&$A6) -> 29118 | C6: =GETPIVOTDATA(""&C$1,Control!$A$20,"Month",""&$A6) -> 42780 | D6: =IFERROR(GETPIVOTDATA(""&B$1,Control!$A$3,"Month",""&$A6),NA()) -> #N/A | E6: =IFERROR(GETPIVOTDATA(""&C$1,Control!$A$3,"Month",""&$A6),NA()) -> #N/A | F6: =$F$14 -> 1545.76 | H6: Friday | I6: FRI | J6: =GETPIVOTDATA(""&I6,Control!$A$3) -> 1164 | K6: =IF(ISNUMBER(MATCH(H6,Control!$A$43:$A$47,0)),Processing!J6,NA()) -> 1164 | L6: =$L$7 -> 229.64 | M6: =L6+K6 -> 1393.64 | N6: =IF(ISNA(K6),"",IF(K6<1000,K6,ROUND(K6/1000,1)&"K")) -> 1.2K
A7: JUN | B7: =GETPIVOTDATA(""&B$1,Control!$A$20,"Month",""&$A7) -> 23300 | C7: =GETPIVOTDATA(""&C$1,Control!$A$20,"Month",""&$A7) -> 36777 | D7: =IFERROR(GETPIVOTDATA(""&B$1,Control!$A$3,"Month",""&$A7),NA()) -> #N/A | E7: =IFERROR(GETPIVOTDATA(""&C$1,Control!$A$3,"Month",""&$A7),NA()) -> #N/A | F7: =$F$14 -> 1545.76 | K7: {=SUM(IFERROR(K2:K6,0))} -> 15366 | L7: =MAX(J2:J6)*4% -> 229.64
A8: JUL | B8: =GETPIVOTDATA(""&B$1,Control!$A$20,"Month",""&$A8) -> 23093 | C8: =GETPIVOTDATA(""&C$1,Control!$A$20,"Month",""&$A8) -> 33575 | D8: =IFERROR(GETPIVOTDATA(""&B$1,Control!$A$3,"Month",""&$A8),NA()) -> #N/A | E8: =IFERROR(GETPIVOTDATA(""&C$1,Control!$A$3,"Month",""&$A8),NA()) -> #N/A | F8: =$F$14 -> 1545.76
A9: AUG | B9: =GETPIVOTDATA(""&B$1,Control!$A$20,"Month",""&$A9) -> 32452 | C9: =GETPIVOTDATA(""&C$1,Control!$A$20,"Month",""&$A9) -> 34422 | D9: =IFERROR(GETPIVOTDATA(""&B$1,Control!$A$3,"Month",""&$A9),NA()) -> #N/A | E9: =IFERROR(GETPIVOTDATA(""&C$1,Control!$A$3,"Month",""&$A9),NA()) -> #N/A | F9: =$F$14 -> 1545.76
A10: SEP | B10: =GETPIVOTDATA(""&B$1,Control!$A$20,"Month",""&$A10) -> 37109 | C10: =GETPIVOTDATA(""&C$1,Control!$A$20,"Month",""&$A10) -> 38532 | D10: =IFERROR(GETPIVOTDATA(""&B$1,Control!$A$3,"Month",""&$A10),NA()) -> #N/A | E10: =IFERROR(GETPIVOTDATA(""&C$1,Control!$A$3,"Month",""&$A10),NA()) -> #N/A | F10: =$F$14 -> 1545.76 | K10: Sales Distribution by Top Product Categories | L10: Top-5 Products | M10: Revenue | N10: Sales
A11: OCT | B11: =GETPIVOTDATA(""&B$1,Control!$A$20,"Month",""&$A11) -> 37602 | C11: =GETPIVOTDATA(""&C$1,Control!$A$20,"Month",""&$A11) -> 43205 | D11: =IFERROR(GETPIVOTDATA(""&B$1,Control!$A$3,"Month",""&$A11),NA()) -> #N/A | E11: =IFERROR(GETPIVOTDATA(""&C$1,Control!$A$3,"Month",""&$A11),NA()) -> #N/A | F11: =$F$14 -> 1545.76 | K11: Product | L11: A | M11: =GETPIVOTDATA(M$10&" "&$L11,Control!$A$3) -> 8185 | N11: =GETPIVOTDATA(N$10&" "&$L11,Control!$A$3) -> 7381.8451 | P11: 72 | Q11: 72 | R11: 72 | S11: 72 | T11: 72
A12: NOV | B12: =GETPIVOTDATA(""&B$1,Control!$A$20,"Month",""&$A12) -> 33906 | C12: =GETPIVOTDATA(""&C$1,Control!$A$20,"Month",""&$A12) -> 43752 | D12: =IFERROR(GETPIVOTDATA(""&B$1,Control!$A$3,"Month",""&$A12),NA()) -> #N/A | E12: =IFERROR(GETPIVOTDATA(""&C$1,Control!$A$3,"Month",""&$A12),NA()) -> #N/A | F12: =$F$14 -> 1545.76 | K12: Product | L12: B | M12: =GETPIVOTDATA(M$10&" "&$L12,Control!$A$3) -> 7567 | N12: =GETPIVOTDATA(N$10&" "&$L12,Control!$A$3) -> 8409.9742 | P12: 72 | Q12: 72 | R12: 72 | S12: 72 | T12: 72
A13: DEC | B13: =GETPIVOTDATA(""&B$1,Control!$A$20,"Month",""&$A13) -> 34372 | C13: =GETPIVOTDATA(""&C$1,Control!$A$20,"Month",""&$A13) -> 41665 | D13: =IFERROR(GETPIVOTDATA(""&B$1,Control!$A$3,"Month",""&$A13),NA()) -> #N/A | E13: =IFERROR(GETPIVOTDATA(""&C$1,Control!$A$3,"Month",""&$A13),NA()) -> #N/A | F13: =$F$14 -> 1545.76 | K13: Product | L13: C | M13: =GETPIVOTDATA(M$10&" "&$L13,Control!$A$3) -> 5405 | N13: =GETPIVOTDATA(N$10&" "&$L13,Control!$A$3) -> 7244.8855 | P13: 72 | Q13: 72 | R13: 72 | S13: 72 | T13: 72
B14: =GETPIVOTDATA("Sum of Investments",Control!$A$3) -> 28026 | C14: =GETPIVOTDATA("Sum of Sales Volume",Control!$A$3) -> 33543 | F14: =MAX(B2:B13)*4% -> 1545.76 | K14: Product | L14: D | M14: =GETPIVOTDATA(M$10&" "&$L14,Control!$A$3) -> 9111 | N14: =GETPIVOTDATA(N$10&" "&$L14,Control!$A$3) -> 4026.7998 | P14: 72 | Q14: 72 | R14: 72 | S14: 72 | T14: 72
A15: Cash Flow Share | B15: =B14/$J$28 -> 0.43454531 | C15: =C14/$J$28 -> 0.52008683 | K15: Product | L15: E | M15: =GETPIVOTDATA(M$10&" "&$L15,Control!$A$3) -> 7567 | N15: =GETPIVOTDATA(N$10&" "&$L15,Control!$A$3) -> 6479.4954
B16: =1-B15 -> 0.56545469 | C16: =1-C15 -> 0.47991317 | M16: {=SUM(IFERROR(M11:M15,0))} -> 37835 | N16: {=SUM(IFERROR(N11:N15,0))} -> 33543
A19: Revenue vs Expenses | B19: Revenue | C19: Expenses | D19: Cursor R | E19: Cursor E | G19: Return on Investment (ROI) | H19: Cursor
A20: JAN | B20: =GETPIVOTDATA(""&B$19,Control!$A$20,"Month",""&$A20) -> 37835 | C20: =GETPIVOTDATA(""&C$19,Control!$A$20,"Month",""&$A20) -> 26660 | D20: =IFERROR(GETPIVOTDATA(""&B$19,Control!$A$3,"Month",""&$A20),NA()) -> 37835 | E20: =IFERROR(GETPIVOTDATA(""&C$19,Control!$A$3,"Month",""&$A20),NA()) -> 26660 | G20: =(B20-C20)/B2 -> 0.39873689 | H20: =IF(ISNA(D20),D20,G20) -> 0.39873689 | J20: ROI | K20: =(B32-C32)/B14 -> 0.39873689 | L20: JANUARY
A21: FEB | B21: =GETPIVOTDATA(""&B$19,Control!$A$20,"Month",""&$A21) -> 48805 | C21: =GETPIVOTDATA(""&C$19,Control!$A$20,"Month",""&$A21) -> 32060 | D21: =IFERROR(GETPIVOTDATA(""&B$19,Control!$A$3,"Month",""&$A21),NA()) -> #N/A | E21: =IFERROR(GETPIVOTDATA(""&C$19,Control!$A$3,"Month",""&$A21),NA()) -> #N/A | G21: =(B21-C21)/B3 -> 0.46318323 | H21: =IF(ISNA(D21),D21,G21) -> #N/A | J21: =IF(K20<0,0,K20) -> 0.39873689 | L21: FEBRUARY
A22: MAR | B22: =GETPIVOTDATA(""&B$19,Control!$A$20,"Month",""&$A22) -> 52169 | C22: =GETPIVOTDATA(""&C$19,Control!$A$20,"Month",""&$A22) -> 35760 | D22: =IFERROR(GETPIVOTDATA(""&B$19,Control!$A$3,"Month",""&$A22),NA()) -> #N/A | E22: =IFERROR(GETPIVOTDATA(""&C$19,Control!$A$3,"Month",""&$A22),NA()) -> #N/A | G22: =(B22-C22)/B4 -> 0.4246196 | H22: =IF(ISNA(D22),D22,G22) -> #N/A | J22: =IF(K20<0,1-J23,1-J21) -> 0.60126311 | L22: MARCH
A23: APR | B23: =GETPIVOTDATA(""&B$19,Control!$A$20,"Month",""&$A23) -> 47883 | C23: =GETPIVOTDATA(""&C$19,Control!$A$20,"Month",""&$A23) -> 36560 | D23: =IFERROR(GETPIVOTDATA(""&B$19,Control!$A$3,"Month",""&$A23),NA()) -> #N/A | E23: =IFERROR(GETPIVOTDATA(""&C$19,Control!$A$3,"Month",""&$A23),NA()) -> #N/A | G23: =(B23-C23)/B5 -> 0.31923652 | H23: =IF(ISNA(D23),D23,G23) -> #N/A | J23: =IF(K20<0,ABS(K20),0) -> 0 | L23: APRIL
A24: MAY | B24: =GETPIVOTDATA(""&B$19,Control!$A$20,"Month",""&$A24) -> 39309 | C24: =GETPIVOTDATA(""&C$19,Control!$A$20,"Month",""&$A24) -> 34220 | D24: =IFERROR(GETPIVOTDATA(""&B$19,Control!$A$3,"Month",""&$A24),NA()) -> #N/A | E24: =IFERROR(GETPIVOTDATA(""&C$19,Control!$A$3,"Month",""&$A24),NA()) -> #N/A | G24: =(B24-C24)/B6 -> 0.17477162 | H24: =IF(ISNA(D24),D24,G24) -> #N/A | J24: Profit | L24: MAY
A25: JUN | B25: =GETPIVOTDATA(""&B$19,Control!$A$20,"Month",""&$A25) -> 31455 | C25: =GETPIVOTDATA(""&C$19,Control!$A$20,"Month",""&$A25) -> 29500 | D25: =IFERROR(GETPIVOTDATA(""&B$19,Control!$A$3,"Month",""&$A25),NA()) -> #N/A | E25: =IFERROR(GETPIVOTDATA(""&C$19,Control!$A$3,"Month",""&$A25),NA()) -> #N/A | G25: =(B25-C25)/B7 -> 0.083905579 | H25: =IF(ISNA(D25),D25,G25) -> #N/A | J25: =B32-C32 -> 11175 | L25: JUNE
A26: JUL | B26: =GETPIVOTDATA(""&B$19,Control!$A$20,"Month",""&$A26) -> 31175 | C26: =GETPIVOTDATA(""&C$19,Control!$A$20,"Month",""&$A26) -> 23820 | D26: =IFERROR(GETPIVOTDATA(""&B$19,Control!$A$3,"Month",""&$A26),NA()) -> #N/A | E26: =IFERROR(GETPIVOTDATA(""&C$19,Control!$A$3,"Month",""&$A26),NA()) -> #N/A | G26: =(B26-C26)/B8 -> 0.31849478 | H26: =IF(ISNA(D26),D26,G26) -> #N/A | L26: JULY
A27: AUG | B27: =GETPIVOTDATA(""&B$19,Control!$A$20,"Month",""&$A27) -> 43810 | C27: =GETPIVOTDATA(""&C$19,Control!$A$20,"Month",""&$A27) -> 19100 | D27: =IFERROR(GETPIVOTDATA(""&B$19,Control!$A$3,"Month",""&$A27),NA()) -> #N/A | E27: =IFERROR(GETPIVOTDATA(""&C$19,Control!$A$3,"Month",""&$A27),NA()) -> #N/A | G27: =(B27-C27)/B9 -> 0.76143227 | H27: =IF(ISNA(D27),D27,G27) -> #N/A | J27: Cash Flow | L27: AUGUST
A28: SEP | B28: =GETPIVOTDATA(""&B$19,Control!$A$20,"Month",""&$A28) -> 50097 | C28: =GETPIVOTDATA(""&C$19,Control!$A$20,"Month",""&$A28) -> 16760 | D28: =IFERROR(GETPIVOTDATA(""&B$19,Control!$A$3,"Month",""&$A28),NA()) -> #N/A | E28: =IFERROR(GETPIVOTDATA(""&C$19,Control!$A$3,"Month",""&$A28),NA()) -> #N/A | G28: =(B28-C28)/B10 -> 0.8983535 | H28: =IF(ISNA(D28),D28,G28) -> #N/A | J28: =B32+C32 -> 64495 | L28: SEPTEMBER
A29: OCT | B29: =GETPIVOTDATA(""&B$19,Control!$A$20,"Month",""&$A29) -> 50762 | C29: =GETPIVOTDATA(""&C$19,Control!$A$20,"Month",""&$A29) -> 17560 | D29: =IFERROR(GETPIVOTDATA(""&B$19,Control!$A$3,"Month",""&$A29),NA()) -> #N/A | E29: =IFERROR(GETPIVOTDATA(""&C$19,Control!$A$3,"Month",""&$A29),NA()) -> #N/A | G29: =(B29-C29)/B11 -> 0.88298495 | H29: =IF(ISNA(D29),D29,G29) -> #N/A | L29: OCTOBER
A30: NOV | B30: =GETPIVOTDATA(""&B$19,Control!$A$20,"Month",""&$A30) -> 45773 | C30: =GETPIVOTDATA(""&C$19,Control!$A$20,"Month",""&$A30) -> 21260 | D30: =IFERROR(GETPIVOTDATA(""&B$19,Control!$A$3,"Month",""&$A30),NA()) -> #N/A | E30: =IFERROR(GETPIVOTDATA(""&C$19,Control!$A$3,"Month",""&$A30),NA()) -> #N/A | G30: =(B30-C30)/B12 -> 0.72296939 | H30: =IF(ISNA(D30),D30,G30) -> #N/A | L30: NOVEMBER
A31: DEC | B31: =GETPIVOTDATA(""&B$19,Control!$A$20,"Month",""&$A31) -> 46402 | C31: =GETPIVOTDATA(""&C$19,Control!$A$20,"Month",""&$A31) -> 26660 | D31: =IFERROR(GETPIVOTDATA(""&B$19,Control!$A$3,"Month",""&$A31),NA()) -> #N/A | E31: =IFERROR(GETPIVOTDATA(""&C$19,Control!$A$3,"Month",""&$A31),NA()) -> #N/A | G31: =(B31-C31)/B13 -> 0.57436285 | H31: =IF(ISNA(D31),D31,G31) -> #N/A | L31: DECEMBER
B32: =GETPIVOTDATA("Sum of Revenue",Control!$A$3) -> 37835 | C32: =GETPIVOTDATA("Sum of Expenses",Control!$A$3) -> 26660

Sheet Control
A3: Row Labels | B3: Sum of Investments | C3: Sum of Sales Volume | D3: Sum of Revenue | E3: Sum of Expenses | F3: Sum of MON | G3: Sum of TUE | H3: Sum of WED | I3: Sum of THU | J3: Sum of FRI | K3: Sum of Sales A | L3: Sum of Sales B | M3: Sum of Sales C | N3: Sum of Sales D | O3: Sum of Sales E | P3: Sum of Revenue A | Q3: Sum of Revenue B | R3: Sum of Revenue C | S3: Sum of Revenue D | T3: Sum of Revenue E
A4: JAN | B4: 28026 | C4: 33543 | D4: 37835 | E4: 26660 | F4: 1511 | G4: 5603 | H4: 5741 | I4: 2858 | J4: 1164 | K4: 7381.8451 | L4: 8409.9742 | M4: 7244.8855 | N4: 4026.7998 | O4: 6479.4954 | P4: 8185 | Q4: 7567 | R4: 5405 | S4: 9111 | T4: 7567
A5: Grand Total | B5: 28026 | C5: 33543 | D5: 37835 | E5: 26660 | F5: 1511 | G5: 5603 | H5: 5741 | I5: 2858 | J5: 1164 | K5: 7381.8451 | L5: 8409.9742 | M5: 7244.8855 | N5: 4026.7998 | O5: 6479.4954 | P5: 8185 | Q5: 7567 | R5: 5405 | S5: 9111 | T5: 7567
A20: Row Labels | B20: Sum of Investments | C20: Sum of Sales Volume | D20: Sum of Revenue | E20: Sum of Expenses
A21: JAN | B21: 28026 | C21: 33543 | D21: 37835 | E21: 26660
A22: FEB | B22: 36152 | C22: 33555 | D22: 48805 | E22: 32060
A23: MAR | B23: 38644 | C23: 38370 | D23: 52169 | E23: 35760
A24: APR | B24: 35469 | C24: 44242 | D24: 47883 | E24: 36560
A25: MAY | B25: 29118 | C25: 42780 | D25: 39309 | E25: 34220
A26: JUN | B26: 23300 | C26: 36777 | D26: 31455 | E26: 29500
A27: JUL | B27: 23093 | C27: 33575 | D27: 31175 | E27: 23820
A28: AUG | B28: 32452 | C28: 34422 | D28: 43810 | E28: 19100
A29: SEP | B29: 37109 | C29: 38532 | D29: 50097 | E29: 16760
A30: OCT | B30: 37602 | C30: 43205 | D30: 50762 | E30: 17560
A31: NOV | B31: 33906 | C31: 43752 | D31: 45773 | E31: 21260
A32: DEC | B32: 34372 | C32: 41665 | D32: 46402 | E32: 26660
A33: Grand Total | B33: 389243 | C33: 464418 | D33: 525475 | E33: 319920
A35: Row Labels
A36: 2024
A37: Grand Total
A42: Row Labels
A43: Tuesday
A44: Wednesday
A45: Thursday
A46: Friday
A47: Grand Total

Sheet Data
A1: Year | B1: Month | C1: Investments | D1: Sales Volume | E1: Revenue | F1: Expenses | G1: MON | H1: TUE | I1: WED | J1: THU | K1: FRI | L1: Sales A | M1: Sales B | N1: Sales C | O1: Sales D | P1: Sales E | Q1: Revenue A | R1: Revenue B | S1: Revenue C | T1: Revenue D | U1: Revenue E
A2: 2025 | B2: JAN | C2: 80017 | D2: 97558 | E2: 112023 | F2: 100740 | G2: 713 | H2: 1140 | I2: 1621 | J2: 1446 | K2: 754 | L2: 27448.095 | M2: 16424.797 | N2: 7872.0363 | O2: 18863.28 | P2: 26949.791 | Q2: 13248 | R2: 26106 | S2: 24158 | T2: 26106 | U2: 22405
A3: 2025 | B3: FEB | C3: 63839 | D3: 109249 | E3: 89374 | F3: 94530 | G3: 1253 | H3: 1650 | I3: 2372 | J3: 1139 | K3: 1036 | L3: 23764.93 | M3: 24933.091 | N3: 18942.267 | O3: 17383.06 | P3: 24225.653 | Q3: 25295 | R3: 15177 | S3: 19898 | T3: 11130 | U3: 17874
A4: 2025 | B4: MAR | C4: 52732 | D4: 114510 | E4: 73824 | F4: 102810 | G4: 669 | H4: 866 | I4: 1521 | J4: 4462 | K4: 1452 | L4: 24276.434 | M4: 12218.542 | N4: 22456.748 | O4: 31424.981 | P4: 24133.295 | Q4: 19686 | R4: 17897 | S4: 12528 | T4: 8948 | U4: 14765
A5: 2025 | B5: APR | C5: 50355 | D5: 106636 | E5: 70497 | F5: 113850 | G5: 1170 | H5: 1781 | I5: 1273 | J5: 1014 | K5: 518 | L5: 16531.862 | M5: 17366.782 | N5: 28381.302 | O5: 27577.001 | P5: 16779.052 | Q5: 19369 | R5: 18799 | S5: 9115 | T5: 9115 | U5: 14099
A6: 2025 | B6: MAY | C6: 57327 | D6: 87133 | E6: 80257 | F6: 106260 | G6: 486 | H6: 1235 | I6: 2145 | J6: 1513 | K6: 338 | L6: 14632.424 | M6: 15003.911 | N6: 21139.092 | O6: 20823.476 | P6: 15534.097 | Q6: 9126 | R6: 17274 | S6: 23792 | T6: 14014 | U6: 16051
A7: 2025 | B7: JUN | C7: 71533 | D7: 76715 | E7: 100146 | F7: 89700 | G7: 1067 | H7: 1554 | I7: 1331 | J7: 1004 | K7: 176 | L7: 15548.793 | M7: 18349.347 | N7: 17570.157 | O7: 13182.381 | P7: 12064.322 | Q7: 14421 | R7: 17626 | S7: 13887 | T7: 34183 | U7: 20029
A8: 2025 | B8: JUL | C8: 88557 | D8: 78093 | E8: 123979 | F8: 88320 | G8: 531 | H8: 1000 | I8: 2408 | J8: 627 | K8: 304 | L8: 18182.577 | M8: 22610.189 | N8: 18390.089 | O8: 8722.1508 | P8: 10187.994 | Q8: 34006 | R8: 28338 | S8: 21254 | T8: 15586 | U8: 24795
A9: 2025 | B9: AUG | C9: 102771 | D9: 93616 | E9: 143879 | F9: 99360 | G9: 1298 | H9: 1472 | I9: 814 | J9: 799 | K9: 354 | L9: 19490.769 | M9: 27354.346 | N9: 25331.62 | O9: 9890.3618 | P9: 11548.904 | Q9: 24858 | R9: 27560 | S9: 35666 | T9: 27020 | U9: 28775
A10: 2025 | B10: SEP | C10: 109735 | D10: 100816 | E10: 153629 | F10: 120060 | G10: 1236 | H10: 1720 | I10: 1512 | J10: 1071 | K10: 168 | L10: 15375.277 | M10: 24337.336 | N10: 31549.815 | O10: 16057.9 | P10: 13495.672 | Q10: 34066 | R10: 18703 | S10: 28722 | T10: 41413 | U10: 30725
A11: 2025 | B11: OCT | C11: 107323 | D11: 90443 | E11: 150252 | F11: 128340 | G11: 420 | H11: 890 | I11: 1583 | J11: 1371 | K11: 458 | L11: 11014.116 | M11: 15341.884 | N11: 26871.387 | O11: 21798.474 | P11: 15417.14 | Q11: 51167 | R11: 25990 | S11: 21929 | T11: 21116 | U11: 30050
A12: 2025 | B12: NOV | C12: 96271 | D12: 82576 | E12: 134779 | F12: 122820 | G12: 337 | H12: 2403 | I12: 2057 | J12: 738 | K12: 211 | L12: 10692.047 | M12: 11348.73 | N12: 19769.97 | O12: 23319.134 | P12: 17446.119 | Q12: 42530 | R12: 28753 | S12: 21565 | T12: 14975 | U12: 26956
A13: 2025 | B13: DEC | C13: 80090 | D13: 88480 | E13: 112126 | F13: 110400 | G13: 1669 | H13: 1773 | I13: 405 | J13: 401 | K13: 304 | L13: 15500.81 | M13: 11835.551 | N13: 14342.623 | O13: 23570.212 | P13: 23230.804 | Q13: 22012 | R13: 18160 | S13: 18160 | T13: 31368 | U13: 22426
... A37: 2024 | B37: DEC | C37: 34372 | D37: 41665 | E37: 46402 | F37: 26660 | G37: 3131 | H37: 4514 | I37: 4313 | J37: 2682 | K37: 707 | L37: 6213.2133 | M37: 8291.855 | N37: 7830.2281 | O37: 9849.9779 | P37: 9479.7257 | Q37: 5924 | R37: 12242 | S37: 5924 | T37: 13032 | U37: 9280

Sheet Resources
C1: Position | D1: Transparency | E1: Angle | G1: Shadow | H1: 60 | I1: 100 | J1: 45 | K1: 135 | L1: 30
B2: #754CB9 | C2: 35 | G2: Shadow | H2: 20 | I2: 100 | J2: 15 | K2: 135 | L2: 3
B3: #519FFB | C3: 65
B4: #EE0078 | C4: 0
B5: #562BFF | C5: 100
B7: #1E2255 | C7: 62
B8: #2B215C | C8: 100 | E8: 135
B9: #4E7AE2 | C9: 0
B10: #3A2058 | C10: 77 | D10: 100
A11: Line | B11: #B7D6FF | C11: 0
A12: Line | B12: #5584ED | C12: 51
A13: Line | B13: #B459A0 | C13: 100
E14: #006FF6
B15: #3C56B2 | C15: 0
B16: #2F4495 | C16: 20 | E16: #002858
B17: #253274 | C17: 50
B18: #1E2255 | C18: 100 | E18: #7A4FF0
A19: Line | B19: #5080DB | C19: 0 | E19: #60A8FF
A20: Line | B20: #6476CE | C20: 20 | E20: #2185FF
A21: Line | B21: #222964 | C21: 100
E22: #00C6D1
E23: #AEACF5
B24: #232C68 | C24: 0
B25: #1C265C | C25: 10
B26: #1E2255 | C26: 100
A27: Line | B27: #6476CE | C27: 0
A28: Line | B28: #222964 | C28: 70
B30: #EE0078 | C30: 0
B31: #6459F9 | C31: 73
A33: Font | B33: #A2ADBE
B36: #43416F
B37: #00C6D1
B38: #F2ECFF
B39: #341EEF
B40: #EE0078
B41: #35386E
B44: #EE0078
B45: #F17EEC
B46: #7A4FF0
B47: #60A8FF
...
